Workbook

Sheet 小車
A1: 重複檢查 | B1: 重複檢查 | C1: # | D1: 中古車編號 | E1: 車身號碼 | F1: 經銷商 | G1: 承辦人員 | H1: 新車品牌 | I1: 送件日期 (YYYY/MM/DD) | J1: 退稅支票受款人 | K1: 是否有中古車 | L1: 案件截止日 | M1: 紙本文件收到日 | N1: First Reviewer | O1: Second Reviewer | P1: 預定送件日期 | Q1: 送件進度 | R1: 回覆內容 1st review 橘色； 2nd review 綠色； 寄信回覆客戶加日期後轉白色；淺藍色為需要再2次追蹤的 | S1: 批次項號 | T1: 車牌 | U1: 寄發匯款通知
A2: =IF(COUNTIF(E:E,E2)>1,"重複","") | B2: =IF(COUNTIF(J:J,J2)>1,"重複","") | C2: A000001 | D2: 50042 | E2: TMBAR0NX1SM057335 | F2: KH | G2: 楊姵瑩/簡郁萱 | H2: Skoda | J2: 林洛仁 | K2: Y | M2: 45917 | N2: Jessie | O2: Sammy | P2: 45944 | Q2: V | R2: 2000cc Ready to go | S2: =VLOOKUP(C2,submitted!A:B,2,FALSE) -> D-2025AB01-2000CC-1 | T2: =VLOOKUP(C2,submitted!A:C,3,FALSE) -> CCL-1231 | U2: =VLOOKUP(T2,'[1]20260201'!$C:$P,14,FALSE) -> 46054
A3: =IF(COUNTIF(E:E,E3)>1,"重複","") | B3: =IF(COUNTIF(J:J,J3)>1,"重複","") | C3: A000002 | D3: 50050 | E3: TMBER9PJ6S4099241 | F3: 原莊 | G3: 廖伊梵 | H3: Skoda | I3: 45917 | J3: 張麗君 | K3: Y | M3: 45917 | N3: Jessie | O3: Sammy | P3: 45944 | Q3: V | R3: 2000cc Ready to go | S3: =VLOOKUP(C3,submitted!A:B,2,FALSE) -> D-2025AB01-2000CC-2 | T3: =VLOOKUP(C3,submitted!A:C,3,FALSE) -> CBY-6753 | U3: =VLOOKUP(T3,'[1]20260201'!$C:$P,14,FALSE) -> 46054
A4: =IF(COUNTIF(E:E,E4)>1,"重複","") -> 重複 | B4: =IF(COUNTIF(J:J,J4)>1,"重複","") -> 重複 | C4: A000003 | D4: 50068 | E4: WVWZZZCD0SW246322 | F4: 宗承 | G4: 薛雅萍 | H4: VW PC | J4: 曾桂芬 | K4: Y | M4: 45917 | N4: Jessie | O4: Sammy | P4: 45944 | Q4: V | R4: 2000cc Ready to go | S4: =VLOOKUP(C4,submitted!A:B,2,FALSE) -> D-2025AB01-2000CC-3 | T4: =VLOOKUP(C4,submitted!A:C,3,FALSE) -> BWR-3880 | U4: =VLOOKUP(T4,'[1]20260201'!$C:$P,14,FALSE) -> 46054
A5: =IF(COUNTIF(E:E,E5)>1,"重複","") | B5: =IF(COUNTIF(J:J,J5)>1,"重複","") | C5: A000004 | D5: 50093 | E5: WAUZZZGY7SA148167 | F5: 奧迪南部汽車 | G5: 鐘莉雯 | H5: Audi | I5: 45922 | J5: 劉家寧 | K5: Y | M5: 45923 | N5: Jessie | O5: Sammy | P5: 45944 | Q5: V | R5: 2000cc Ready to go | S5: =VLOOKUP(C5,submitted!A:B,2,FALSE) -> D-2025AB01-2000CC-4 | T5: =VLOOKUP(C5,submitted!A:C,3,FALSE) -> CAH-1122 | U5: =VLOOKUP(T5,'[1]20260201'!$C:$P,14,FALSE) -> 46054
A6: =IF(COUNTIF(E:E,E6)>1,"重複","") | B6: =IF(COUNTIF(J:J,J6)>1,"重複","") | C6: A000005 | D6: 50100 | E6: TMBLD9PS9ST075259 | F6: KH | G6: 施孟佳/林子森 | H6: Skoda | I6: 45922 | J6: 龔家弘 | K6: Y | M6: 45923 | N6: Jessie | O6: Sammy | P6: 45944 | Q6: V | R6: 2000cc Ready to go | S6: =VLOOKUP(C6,submitted!A:B,2,FALSE) -> D-2025AB01-2000CC-5 | T6: =VLOOKUP(C6,submitted!A:C,3,FALSE) -> CBM-5051 | U6: =VLOOKUP(T6,'[1]20260201'!$C:$P,14,FALSE) -> 46054
A7: =IF(COUNTIF(E:E,E7)>1,"重複","") | B7: =IF(COUNTIF(J:J,J7)>1,"重複","") | C7: A000006 | D7: 50116 | E7: WVGZZZC12RY088372 | F7: 進東-花蓮 | G7: 李秋潔 | H7: VW PC | I7: 45919 | J7: 温芮妤 | K7: Y | M7: 45923 | N7: Jessie | O7: Sammy | P7: 45944 | Q7: V | R7: 2000cc Ready to go | S7: =VLOOKUP(C7,submitted!A:B,2,FALSE) -> D-2025AB01-2000CC-6 | T7: =VLOOKUP(C7,submitted!A:C,3,FALSE) -> BZS-2592 | U7: =VLOOKUP(T7,'[1]20260201'!$C:$P,14,FALSE) -> 46054
A8: =IF(COUNTIF(E:E,E8)>1,"重複","") | B8: =IF(COUNTIF(J:J,J8)>1,"重複","") | C8: A000007 | D8: 50119 | E8: TMBER9PJ5S4091941 | F8: 鈞銓 | G8: 蘇燕玲 | H8: Skoda | I8: 45925 | J8: 劉倧廷 | K8: Y | M8: 45926 | N8: Jessie | O8: Sammy | P8: 45944 | Q8: V | R8: 2000cc Ready to go | S8: =VLOOKUP(C8,submitted!A:B,2,FALSE) -> D-2025AB01-2000CC-7 | T8: =VLOOKUP(C8,submitted!A:C,3,FALSE) -> CAB-9552 | U8: =VLOOKUP(T8,'[1]20260201'!$C:$P,14,FALSE) -> 46054
A9: =IF(COUNTIF(E:E,E9)>1,"重複","") | B9: =IF(COUNTIF(J:J,J9)>1,"重複","") | C9: A000008 | D9: 50123 | E9: WVGZZZC13RY089062 | F9: SWC | G9: 陳昱鈞/張馨瞳 | H9: VW PC | I9: 45925 | J9: 林吉釧 | K9: Y | M9: 45926 | N9: Jessie | O9: Sammy | P9: 45944 | Q9: V | R9: 2000cc Ready to go | S9: =VLOOKUP(C9,submitted!A:B,2,FALSE) -> D-2025AB01-2000CC-8 | T9: =VLOOKUP(C9,submitted!A:C,3,FALSE) -> CBM-3893 | U9: =VLOOKUP(T9,'[1]20260201'!$C:$P,14,FALSE) -> 46054
A10: =IF(COUNTIF(E:E,E10)>1,"重複","") | B10: =IF(COUNTIF(J:J,J10)>1,"重複","") | C10: A000009 | D10: 50128 | E10: WVWZZZCD4SW198579 | F10: 揚昌 | G10: 吳益綸 | H10: VW PC | J10: 王薇清 | K10: Y | M10: 45926 | N10: Jessie | O10: Sammy | P10: 45944 | Q10: V | R10: 2000cc Ready to go | S10: =VLOOKUP(C10,submitted!A:B,2,FALSE) -> D-2025AB01-2000CC-9 | T10: =VLOOKUP(C10,submitted!A:C,3,FALSE) -> CAR-7378 | U10: =VLOOKUP(T10,'[1]20260201'!$C:$P,14,FALSE) -> 46054
A11: =IF(COUNTIF(E:E,E11)>1,"重複","") | B11: =IF(COUNTIF(J:J,J11)>1,"重複","") | C11: A000010 | D11: 50139 | E11: TMBJV0NX5SY151562 | F11: 新竹吉揚 | G11: 黃子芸 | H11: Skoda | I11: 45926 | J11: 黃美珠 | K11: Y | L11: 46096 | M11: 45930 | N11: Jessie | O11: Sammy | P11: 45951 | Q11: V | R11: 2000cc Ready to go | S11: =VLOOKUP(C11,submitted!A:B,2,FALSE) -> D-2025AB01-2000CC-10 | T11: =VLOOKUP(C11,submitted!A:C,3,FALSE) -> BZT-5216 | U11: =VLOOKUP(T11,'[1]20260201'!$C:$P,14,FALSE) -> 46054
A12: =IF(COUNTIF(E:E,E12)>1,"重複","") | B12: =IF(COUNTIF(J:J,J12)>1,"重複","") | C12: A000011 | D12: 50140 | E12: TMBLG9PS7ST093086 | F12: 新竹吉揚 | G12: 黃凱笠 | H12: Skoda | I12: 45926 | J12: 吳啓多 | K12: Y | L12: 46091 | M12: 45930 | N12: Jessie | O12: Sammy | P12: 45951 | Q12: V | R12: 2000cc Ready to go | S12: =VLOOKUP(C12,submitted!A:B,2,FALSE) -> D-2025AB01-2000CC-11 | T12: =VLOOKUP(C12,submitted!A:C,3,FALSE) -> CCN-2198 | U12: =VLOOKUP(T12,'[1]20260201'!$C:$P,14,FALSE) -> 46054
A13: =IF(COUNTIF(E:E,E13)>1,"重複","") | B13: =IF(COUNTIF(J:J,J13)>1,"重複","") | C13: A000012 | D13: 50141 | E13: TMBGK9NW0S3135992 | F13: 新竹吉揚 | G13: 黃子芸 | H13: Skoda | I13: 45926 | J13: 江幸娥 | K13: Y | L13: 46091 | M13: 45930 | N13: Jessie | O13: Sammy | P13: 45951 | Q13: V | R13: 2000cc Ready to go | S13: =VLOOKUP(C13,submitted!A:B,2,FALSE) -> D-2025AB01-2000CC-12 | T13: =VLOOKUP(C13,submitted!A:C,3,FALSE) -> CAR-2951 | U13: =VLOOKUP(T13,'[1]20260201'!$C:$P,14,FALSE) -> 46054
A14: =IF(COUNTIF(E:E,E14)>1,"重複","") -> 重複 | B14: =IF(COUNTIF(J:J,J14)>1,"重複","") -> 重複 | C14: A000013 | D14: 50144 | E14: WAUZZZGY1SA147581 | F14: 台奧北區 | G14: 廖苡伶 | H14: Audi | I14: 9/30業務徐至正親送 | J14: 王怡今 | K14: Y | L14: 46107 | M14: 45930 | N14: Jessie | O14: Sammy | P14: 45951 | Q14: V | R14: 2000cc Ready to go | S14: =VLOOKUP(C14,submitted!A:B,2,FALSE) -> D-2025AB01-2000CC-13 | T14: =VLOOKUP(C14,submitted!A:C,3,FALSE) -> CCL-5807 | U14: =VLOOKUP(T14,'[1]20260201'!$C:$P,14,FALSE) -> 46054
A15: =IF(COUNTIF(E:E,E15)>1,"重複","") -> 重複 | B15: =IF(COUNTIF(J:J,J15)>1,"重複","") -> 重複 | C15: A000014 | D15: 50145 | E15: WAUZZZGY5SA152234 | F15: 台奧北區 | G15: 廖苡伶 | H15: Audi | I15: 9/30業務徐至正親送 | J15: 李玉蘭 | K15: Y | L15: 46104 | M15: 45930 | N15: Jessie | O15: Sammy | P15: 45951 | Q15: V | R15: 2000cc Ready to go | S15: =VLOOKUP(C15,submitted!A:B,2,FALSE) -> D-2025AB01-2000CC-14 | T15: =VLOOKUP(C15,submitted!A:C,3,FALSE) -> BXV-8237 | U15: =VLOOKUP(T15,'[1]20260201'!$C:$P,14,FALSE) -> 46054
A16: =IF(COUNTIF(E:E,E16)>1,"重複","") | B16: =IF(COUNTIF(J:J,J16)>1,"重複","") | C16: A000015 | D16: 50151 | E16: TMBEK9NW6S3143439 | F16: 鈞銓 | G16: 蘇燕玲 | H16: Skoda | I16: 45926 | J16: 江惠廷 | K16: Y | L16: 46096 | M16: 45930 | N16: Jessie | O16: Sammy | P16: 45951 | Q16: V | R16: 2000cc Ready to go | S16: =VLOOKUP(C16,submitted!A:B,2,FALSE) -> D-2025AB01-2000CC-15 | T16: =VLOOKUP(C16,submitted!A:C,3,FALSE) -> CBN-0990 | U16: =VLOOKUP(T16,'[1]20260201'!$C:$P,14,FALSE) -> 46054
A17: =IF(COUNTIF(E:E,E17)>1,"重複","") -> 重複 | B17: =IF(COUNTIF(J:J,J17)>1,"重複","") -> 重複 | C17: A000016 | D17: 50152 | E17: TMBJR0NX7SY151387 | F17: 金元三 | G17: 丁子竣 | H17: Skoda | I17: 45926 | J17: 蔡幸延 | K17: Y | L17: 46097 | M17: 45930 | N17: Jessie | O17: Sammy | P17: 45951 | Q17: V | R17: 2000cc Ready to go | S17: =VLOOKUP(C17,submitted!A:B,2,FALSE) -> D-2025AB01-2000CC-16 | T17: =VLOOKUP(C17,submitted!A:C,3,FALSE) -> CBB-0765 | U17: =VLOOKUP(T17,'[1]20260201'!$C:$P,14,FALSE) -> 46054
A18: =IF(COUNTIF(E:E,E18)>1,"重複","") -> 重複 | B18: =IF(COUNTIF(J:J,J18)>1,"重複","") -> 重複 | C18: A000017 | D18: 50153 | E18: TMBEK9PJ0S4096033 | F18: 金元三 | G18: 丁子竣 | H18: Skoda | I18: 45926 | J18: 胡慕昀 | K18: Y | L18: 46096 | M18: 45930 | N18: Jessie | O18: Sammy | P18: 45951 | Q18: V | R18: 2000cc Ready to go | S18: =VLOOKUP(C18,submitted!A:B,2,FALSE) -> D-2025AB01-2000CC-17 | T18: =VLOOKUP(C18,submitted!A:C,3,FALSE) -> CAR-0232 | U18: =VLOOKUP(T18,'[1]20260201'!$C:$P,14,FALSE) -> 46054
A19: =IF(COUNTIF(E:E,E19)>1,"重複","") -> 重複 | B19: =IF(COUNTIF(J:J,J19)>1,"重複","") -> 重複 | C19: A000018 | D19: 50154 | E19: TMBER9PJ7S4101837 | F19: 金元三 | G19: 丁子竣 | H19: Skoda | I19: 45926 | J19: 吳宜蓁 | K19: Y | L19: 46103 | M19: 45930 | N19: Jessie | O19: Sammy | P19: 45951 | Q19: V | R19: 2000cc Ready to go | S19: =VLOOKUP(C19,submitted!A:B,2,FALSE) -> D-2025AB01-2000CC-18 | T19: =VLOOKUP(C19,submitted!A:C,3,FALSE) -> CBB-1765 | U19: =VLOOKUP(T19,'[1]20260201'!$C:$P,14,FALSE) -> 46054
A20: =IF(COUNTIF(E:E,E20)>1,"重複","") -> 重複 | B20: =IF(COUNTIF(J:J,J20)>1,"重複","") -> 重複 | C20: A000019 | D20: 50157 | E20: TMBJV0NX4SY152556 | F20: 金元三 | G20: 丁子竣 | H20: Skoda | I20: 45932 | J20: 王銘宏 | K20: Y | L20: 46107 | M20: 45930 | N20: Jessie | O20: Sammy | P20: 45951 | Q20: V | R20: 2000cc Ready to go | S20: =VLOOKUP(C20,submitted!A:B,2,FALSE) -> D-2025AB01-2000CC-19 | T20: =VLOOKUP(C20,submitted!A:C,3,FALSE) -> CAY-8580 | U20: =VLOOKUP(T20,'[1]20260201'!$C:$P,14,FALSE) -> 46054
A21: =IF(COUNTIF(E:E,E21)>1,"重複","") -> 重複 | B21: =IF(COUNTIF(J:J,J21)>1,"重複","") -> 重複 | C21: A000020 | D21: 50158 | E21: TMBLP0NZXSC057792 | F21: 喬順 | G21: 蘇妍文 | H21: Skoda | J21: 王裕嘉 | K21: Y | L21: 46107 | M21: 45930 | N21: Jessie | O21: Sammy | P21: 45951 | Q21: V | R21: 2000cc Ready to go | S21: =VLOOKUP(C21,submitted!A:B,2,FALSE) -> D-2025AB01-2000CC-20 | T21: =VLOOKUP(C21,submitted!A:C,3,FALSE) -> CBS-0579 | U21: =VLOOKUP(T21,'[1]20260201'!$C:$P,14,FALSE) -> 46054
A22: =IF(COUNTIF(E:E,E22)>1,"重複","") | B22: =IF(COUNTIF(J:J,J22)>1,"重複","") | C22: A000021 | D22: 50163 | E22: WVWZZZAW9SU003317 | F22: SWK | G22: 李姸樺 | H22: VW PC | I22: 45923 | J22: 楊怡容 | K22: Y | L22: 46103 | M22: 45930 | N22: Jessie | O22: Sammy | P22: 45951 | Q22: V | R22: 2000cc Ready to go | S22: =VLOOKUP(C22,submitted!A:B,2,FALSE) -> D-2025AB01-2000CC-21 | T22: =VLOOKUP(C22,submitted!A:C,3,FALSE) -> CCB-0523 | U22: =VLOOKUP(T22,'[1]20260201'!$C:$P,14,FALSE) -> 46054
A23: =IF(COUNTIF(E:E,E23)>1,"重複","") | B23: =IF(COUNTIF(J:J,J23)>1,"重複","") | C23: A000022 | D23: 50167 | E23: WVWZZZCJ6SD066666 | F23: SWP | G23: 林素卿 | H23: VW PC | J23: 詹家瑀 | K23: Y | L23: 46105 | M23: 45930 | N23: Jessie | O23: Sammy | P23: 45951 | Q23: V | R23: 2000cc Ready to go | S23: =VLOOKUP(C23,submitted!A:B,2,FALSE) -> D-2025AB01-2000CC-22 | T23: =VLOOKUP(C23,submitted!A:C,3,FALSE) -> CBK-1286 | U23: =VLOOKUP(T23,'[1]20260201'!$C:$P,14,FALSE) -> 46054
A24: =IF(COUNTIF(E:E,E24)>1,"重複","") | B24: =IF(COUNTIF(J:J,J24)>1,"重複","") | C24: A000023 | D24: 50169 | E24: WVGZZZC1XRY069293 | F24: SWC | G24: 陳昱鈞/陳奕良 | H24: VW PC | I24: 45932 | J24: 鄭夙玲 | K24: Y | L24: 46097 | M24: 45930 | N24: Jessie | O24: Sammy | P24: 45951 | Q24: V | R24: 2000cc Ready to go | S24: =VLOOKUP(C24,submitted!A:B,2,FALSE) -> D-2025AB01-2000CC-23 | T24: =VLOOKUP(C24,submitted!A:C,3,FALSE) -> CBN-0712 | U24: =VLOOKUP(T24,'[1]20260201'!$C:$P,14,FALSE) -> 46054
A25: =IF(COUNTIF(E:E,E25)>1,"重複","") | B25: =IF(COUNTIF(J:J,J25)>1,"重複","") | C25: A000024 | D25: 50172 | E25: WVGZZZ5N6RM214109 | F25: SWC | G25: 陳昱鈞/洪翊展 | H25: VW PC | I25: 45932 | J25: 張銣育 | K25: Y | L25: 46107 | M25: 45930 | N25: Jessie | O25: Sammy | P25: 45951 | Q25: V | R25: 2000cc Ready to go | S25: =VLOOKUP(C25,submitted!A:B,2,FALSE) -> D-2025AB01-2000CC-24 | T25: =VLOOKUP(C25,submitted!A:C,3,FALSE) -> CBQ-0399 | U25: =VLOOKUP(T25,'[1]20260201'!$C:$P,14,FALSE) -> 46054
A26: =IF(COUNTIF(E:E,E26)>1,"重複","") | B26: =IF(COUNTIF(J:J,J26)>1,"重複","") | C26: A000025 | D26: 50176 | E26: TMBJR9NU4S5072223 | F26: KH | G26: 葉珈妤/李柏維 | H26: Skoda | J26: 陳鈺方 | K26: Y | L26: 46111 | M26: 45939 | N26: Jessie | O26: Sammy | P26: 45950 | Q26: V | R26: 2000cc Ready to go | S26: =VLOOKUP(C26,submitted!A:B,2,FALSE) -> D-2025AB02-2000CC-1 | T26: =VLOOKUP(C26,submitted!A:C,3,FALSE) -> CAE-3782 | U26: =VLOOKUP(T26,'[1]20260201'!$C:$P,14,FALSE) -> 46054
A27: =IF(COUNTIF(E:E,E27)>1,"重複","") | B27: =IF(COUNTIF(J:J,J27)>1,"重複","") -> 重複 | C27: A000026 | D27: 50181 | E27: WAUZZZGY4SA153004 | F27: TCH | G27: 王美婉 | H27: Audi | I27: 45883 | J27: 王芊莉 | K27: Y | L27: 46106 | M27: 45939 | N27: Jessie | O27: Sammy | P27: 45950 | Q27: V | R27: 2000cc Ready to go | S27: =VLOOKUP(C27,submitted!A:B,2,FALSE) -> D-2025AB02-2000CC-2 | T27: =VLOOKUP(C27,submitted!A:C,3,FALSE) -> CCB-6818 | U27: =VLOOKUP(T27,'[1]20260201'!$C:$P,14,FALSE) -> 46054
A28: =IF(COUNTIF(E:E,E28)>1,"重複","") | B28: =IF(COUNTIF(J:J,J28)>1,"重複","") | C28: A000027 | D28: 50183 | E28: WVWZZZCD3SW209684 | F28: BSS1 | G28: 潘玟宏 | H28: VW PC | I28: 45930 | J28: 呂湘惠 | K28: Y | L28: 46100 | M28: 45939 | N28: Jessie | O28: Sammy | P28: 45950 | Q28: V | R28: 2000cc Ready to go | S28: =VLOOKUP(C28,submitted!A:B,2,FALSE) -> D-2025AB02-2000CC-3 | T28: =VLOOKUP(C28,submitted!A:C,3,FALSE) -> BWX-6706 | U28: =VLOOKUP(T28,'[1]20260201'!$C:$P,14,FALSE) -> 46054
A29: =IF(COUNTIF(E:E,E29)>1,"重複","") | B29: =IF(COUNTIF(J:J,J29)>1,"重複","") | C29: A000028 | D29: 50184 | E29: TMBER9PJXS4085942 | F29: 喬順 | G29: 蘇妍文 | H29: Skoda | J29: 廖偉廷 | K29: Y | L29: 46106 | M29: 45939 | N29: Jessie | O29: Sammy | P29: 45950 | Q29: V | R29: 2000cc Ready to go | S29: =VLOOKUP(C29,submitted!A:B,2,FALSE) -> D-2025AB02-2000CC-4 | T29: =VLOOKUP(C29,submitted!A:C,3,FALSE) -> CAR-6771 | U29: =VLOOKUP(T29,'[1]20260201'!$C:$P,14,FALSE) -> 46054
A30: =IF(COUNTIF(E:E,E30)>1,"重複","") | B30: =IF(COUNTIF(J:J,J30)>1,"重複","") | C30: A000029 | D30: 50186 | E30: TMBLG9PS9ST101009 | F30: 喬順 | G30: 蘇妍文 | H30: Skoda | J30: 全慶五金行店料行 | K30: Y | L30: 46111 | M30: 45939 | N30: Jessie | O30: Sammy | P30: 45950 | Q30: V | R30: 2000cc Ready to go | S30: =VLOOKUP(C30,submitted!A:B,2,FALSE) -> D-2025AB02-2000CC-5 | T30: =VLOOKUP(C30,submitted!A:C,3,FALSE) -> CAR-6395 | U30: =VLOOKUP(T30,'[1]20260201'!$C:$P,14,FALSE) -> 46054
A31: =IF(COUNTIF(E:E,E31)>1,"重複","") | B31: =IF(COUNTIF(J:J,J31)>1,"重複","") | C31: A000030 | D31: 50187 | E31: TMBER9PJ0S4102408 | F31: 新竹吉揚 | G31: 黃凱笠 | H31: Skoda | I31: 45933 | J31: 羅欣怡 | K31: Y | L31: 46103 | M31: 45939 | N31: Jessie | O31: Sammy | P31: 45950 | Q31: V | R31: 2000cc Ready to go | S31: =VLOOKUP(C31,submitted!A:B,2,FALSE) -> D-2025AB02-2000CC-6 | T31: =VLOOKUP(C31,submitted!A:C,3,FALSE) -> BZF-3196 | U31: =VLOOKUP(T31,'[1]20260201'!$C:$P,14,FALSE) -> 46054
A32: =IF(COUNTIF(E:E,E32)>1,"重複","") | B32: =IF(COUNTIF(J:J,J32)>1,"重複","") | C32: A000031 | D32: 50188 | E32: TMBJR9NU7S5082938 | F32: 新竹吉揚 | G32: 黃凱笠 | H32: Skoda | I32: 45933 | J32: 孫淑賢 | K32: Y | L32: 46099 | M32: 45939 | N32: Jessie | O32: Sammy | P32: 45950 | Q32: V | R32: 2000cc Ready to go | S32: =VLOOKUP(C32,submitted!A:B,2,FALSE) -> D-2025AB02-2000CC-7 | T32: =VLOOKUP(C32,submitted!A:C,3,FALSE) -> CBD-1616 | U32: =VLOOKUP(T32,'[1]20260201'!$C:$P,14,FALSE) -> 46054
A33: =IF(COUNTIF(E:E,E33)>1,"重複","") | B33: =IF(COUNTIF(J:J,J33)>1,"重複","") | C33: A000032 | D33: 50189 | E33: TMBGK9NW6S3134491 | F33: 新竹吉揚 | G33: 黃子芸 | H33: Skoda | I33: 45933 | J33: 呂恩綺 | K33: Y | L33: 46105 | M33: 45939 | N33: Jessie | O33: Sammy | P33: 45950 | Q33: V | R33: 2000cc Ready to go | S33: =VLOOKUP(C33,submitted!A:B,2,FALSE) -> D-2025AB02-2000CC-8 | T33: =VLOOKUP(C33,submitted!A:C,3,FALSE) -> BZF-3208 | U33: =VLOOKUP(T33,'[1]20260201'!$C:$P,14,FALSE) -> 46054
A34: =IF(COUNTIF(E:E,E34)>1,"重複","") | B34: =IF(COUNTIF(J:J,J34)>1,"重複","") | C34: A000033 | D34: 50190 | E34: TMBJB9PS4ST084187 | F34: 新竹吉揚 | G34: 黃子芸 | H34: Skoda | I34: 45933 | J34: 王榆婷 | K34: Y | L34: 46107 | M34: 45939 | N34: Jessie | O34: Sammy | P34: 45950 | Q34: V | R34: 2000cc Ready to go | S34: =VLOOKUP(C34,submitted!A:B,2,FALSE) -> D-2025AB02-2000CC-9 | T34: =VLOOKUP(C34,submitted!A:C,3,FALSE) -> BZP-3528 | U34: =VLOOKUP(T34,'[1]20260201'!$C:$P,14,FALSE) -> 46054
A35: =IF(COUNTIF(E:E,E35)>1,"重複","") | B35: =IF(COUNTIF(J:J,J35)>1,"重複","") | C35: A000034 | D35: 50191 | E35: TMBJR0NX9SY150645 | F35: 鈞銓 | G35: 鐘友君 | H35: Skoda | I35: 45933 | J35: 吳定穎 | K35: Y | L35: 46092 | M35: 45939 | N35: Jessie | O35: Sammy | P35: 45950 | Q35: V | R35: 2000cc Ready to go | S35: =VLOOKUP(C35,submitted!A:B,2,FALSE) -> D-2025AB02-2000CC-10 | T35: =VLOOKUP(C35,submitted!A:C,3,FALSE) -> CAD-2661 | U35: =VLOOKUP(T35,'[1]20260201'!$C:$P,14,FALSE) -> 46054
A36: =IF(COUNTIF(E:E,E36)>1,"重複","") | B36: =IF(COUNTIF(J:J,J36)>1,"重複","") -> 重複 | C36: A000035 | D36: 50194 | E36: TMBER9PJ7S4102082 | F36: 鈞銓 | G36: 鐘友君 | H36: Skoda | I36: 45933 | J36: 林育如 | K36: Y | L36: 46097 | M36: 45939 | N36: Jessie | O36: Sammy | P36: 45950 | Q36: V | R36: 2000cc Ready to go | S36: =VLOOKUP(C36,submitted!A:B,2,FALSE) -> D-2025AB02-2000CC-11 | T36: =VLOOKUP(C36,submitted!A:C,3,FALSE) -> CBM-6139 | U36: =VLOOKUP(T36,'[1]20260201'!$C:$P,14,FALSE) -> 46054
A37: =IF(COUNTIF(E:E,E37)>1,"重複","") -> 重複 | B37: =IF(COUNTIF(J:J,J37)>1,"重複","") -> 重複 | C37: A000036 | D37: 50196 | E37: TMBER9PJ6S4092046 | F37: TPS尚鵬 | G37: 蔡詩晴 | H37: Skoda | I37: 45937 | J37: 韓定華 | K37: Y | L37: 46093 | M37: 45939 | N37: Jessie | O37: Sammy | P37: 45950 | Q37: V | R37: 2000cc Ready to go | S37: =VLOOKUP(C37,submitted!A:B,2,FALSE) -> D-2025AB02-2000CC-12 | T37: =VLOOKUP(C37,submitted!A:C,3,FALSE) -> CAY-2362 | U37: =VLOOKUP(T37,'[1]20260201'!$C:$P,14,FALSE) -> 46054
A38: =IF(COUNTIF(E:E,E38)>1,"重複","") -> 重複 | B38: =IF(COUNTIF(J:J,J38)>1,"重複","") -> 重複 | C38: A000037 | D38: 50198 | E38: WVGZZZ5N5RM208320 | F38: 宗承 | G38: 薛雅萍 | H38: VW PC | J38: 周昉蓉 | K38: Y | L38: 46113 | M38: 45939 | N38: Jessie | O38: Sammy | P38: 45950 | Q38: V | R38: 2000cc Ready to go | S38: =VLOOKUP(C38,submitted!A:B,2,FALSE) -> D-2025AB02-2000CC-13 | T38: =VLOOKUP(C38,submitted!A:C,3,FALSE) -> CBP-1735 | U38: =VLOOKUP(T38,'[1]20260201'!$C:$P,14,FALSE) -> 46054
A39: =IF(COUNTIF(E:E,E39)>1,"重複","") -> 重複 | B39: =IF(COUNTIF(J:J,J39)>1,"重複","") -> 重複 | C39: A000038 | D39: 50199 | E39: WVGZZZ5N3RM208459 | F39: 宗承 | G39: 薛雅萍 | H39: VW PC | J39: 陳淨馨 | K39: Y | L39: 46107 | M39: 45939 | N39: Jessie | O39: Sammy | P39: 45950 | Q39: V | R39: 2000cc Ready to go | S39: =VLOOKUP(C39,submitted!A:B,2,FALSE) -> D-2025AB02-2000CC-14 | T39: =VLOOKUP(C39,submitted!A:C,3,FALSE) -> CCB-0805 | U39: =VLOOKUP(T39,'[1]20260201'!$C:$P,14,FALSE) -> 46054
A40: =IF(COUNTIF(E:E,E40)>1,"重複","") -> 重複 | B40: =IF(COUNTIF(J:J,J40)>1,"重複","") -> 重複 | C40: A000039 | D40: 50200 | E40: WVGZZZCT5SW561779 | F40: 宗承 | G40: 薛雅萍 | H40: VW PC | J40: 趙鈴娟 | K40: Y | L40: 46104 | M40: 45939 | N40: Jessie | O40: Sammy | P40: 45950 | Q40: V | R40: 2000cc Ready to go | S40: =VLOOKUP(C40,submitted!A:B,2,FALSE) -> D-2025AB02-2000CC-15 | T40: =VLOOKUP(C40,submitted!A:C,3,FALSE) -> CAA-9708 | U40: =VLOOKUP(T40,'[1]20260201'!$C:$P,14,FALSE) -> 46054
...

Sheet 匯款資料
A1: NO | B1: 中古車No | C1: 車身號碼 | D1: 收款人 | E1: ID | F1: 28.金融機構類別 | G1: 29.銀行代碼 | H1: 31.分行代碼 | I1: 32.退稅帳號 | J1: 33.電話 | K1: 34.通訊地址
B2: 50042 | C2: TMBAR0NX1SM057335 | D2: 林洛仁 | E2: D122814824 | F2: B | G2: 822 | H2: 0358 | I2: 358540794913 | J2: 0983041659 | K2: 台南市永康區永二街193巷1弄10號
B3: 50050 | C3: TMBER9PJ6S4099241 | D3: 張麗君 | E3: P222882369 | F3: B | G3: 822 | H3: 0462 | I3: 462540200649 | J3: 0920907135 | K3: 雲林縣崙背鄉西榮村3鄰正心街32號
B4: 50068 | C4: WVWZZZCD0SW246322 | D4: 曾桂芬 | E4: N223638800 | F4: B | G4: 004 | H4: 1436 | I4: 143004211952 | J4: 0919232864 | K4: 彰化縣鹿港鎮謝厝巷10之23號
B5: 50093 | C5: WAUZZZGY7SA148167 | D5: 劉家寧 | E5: R224478525 | F5: B | G5: 822 | H5: 0358 | I5: 358540788495 | J5: 0966481657 | K5: 台南市永康區國光八街12巷3弄2號
B6: 50100 | C6: TMBLD9PS9ST075259 | D6: 龔家弘 | E6: T122845475 | F6: P | G6: 700 | H6: 0021 | I6: 00713490264434 | J6: 0930600666 | K6: 屏東縣屏東市古松西巷385之8號
B7: 50116 | C7: WVGZZZC12RY088372 | D7: 温芮妤 | E7: U221359419 | F7: B | G7: 807 | H7: 1217 | I7: 06801800534823 | J7: 0921580560 | K7: 花蓮市國盛四街65號4樓之2
B8: 50119 | C8: TMBER9PJ5S4091941 | D8: 劉倧廷 | E8: Q121376665 | F8: B | G8: 009 | H8: 5772 | I8: 57729503152000 | J8: 0935759605 | K8: 桃園市八德區廣福路20巷27弄9號5樓
B9: 50123 | C9: WVGZZZC13RY089062 | D9: 林吉釧 | E9: B120070368 | F9: B | G9: 822 | H9: 1160 | I9: 160540088011 | J9: 0910-414700 | K9: 台中市西屯區大墩20街183號5樓之1
B10: 50128 | C10: WVWZZZCD4SW198579 | D10: 王薇清 | E10: H222255465 | F10: B | G10: 822 | H10: 0129 | I10: 129537982802 | J10: 0938396633 | K10: 桃園市中壢區中山東路3段405巷11號
B11: 50167 | C11: WVWZZZCJ6SD066666 | D11: 詹家瑀 | E11: F228551268 | F11: B | G11: 822 | H11: 1300 | I11: 300540116866 | J11: 0958672655 | K11: 新北市新莊區龍安路106巷6弄1號9樓
B12: 50168 | C12: WV2ZZZSK9SX110671 | D12: 范瑞騰 | E12: M120272478 | F12: B | G12: 008 | H12: 1784 | I12: 178200361049 | J12: 0989732101 | K12: 新北市三重區正義北路338巷18號2樓
B13: 50169 | C13: WVGZZZC1XRY069293 | D13: 鄭夙玲 | E13: D220251554 | F13: B | G13: 012 | H13: 7222 | I13: 00722221149195 | J13: 0931--656871 | K13: 台中市北屯區平和里9鄰梅川西路4段286號8樓之7號
... B20: 50176 | C20: TMBJR9NU4S5072223 | D20: 陳鈺方 | E20: R223767658 | F20: B | G20: 004 | H20: 0288 | I20: 028002005119 | J20: 0925260612 | K20: 台東縣蘭嶼鎮東清村野銀32號
B21: 50177 | C21: WAUZZZGY7SA143731 | D21: 顏明儀 | E21: F224939248 | F21: P | J21: 0920342452 | K21: 台北市士林區華齡街1號6樓之3
B22: 50178 | C22: WAUZZZGAXRA043667 | D22: 黃芯寧 | E22: H224298780 | F22: B | G22: 013 | H22: 0224 | I22: 022506594964 | J22: 0930972751 | K22: 桃園市觀音區嘉富路1189巷15號
B23: 50179 | C23: WAUZZZ4M1SD034679 | D23: 黃明琪 | E23: E224623913 | F23: P | G23: 700 | H23: 0021 | I23: 00413980845661 | J23: 0928009628 | K23: 高雄市前鎮區公正路168號
B24: 50180 | C24: WAUZZZGB7RR038310 | D24: 湯驛順 | E24: N123331411 | F24: B | G24: 004 | H24: 0794 | I24: 079004650943 | J24: 0952666193 | K24: 台中市南區工學二路117號5樓-3
B25: 50181 | C25: WAUZZZGY4SA153004 | D25: 王芊莉 | E25: N224240902 | F25: B | G25: 006 | H25: 1184 | I25: 1184872082881 | J25: 0988616339 | K25: 台中市西屯區順和七街30號5樓
B26: 50182 | C26: WAUZZZGY2SA134144 | D26: 紀惠瑜 | E26: B221912107 | F26: B | G26: 822 | H26: 0288 | I26: 288540355095 | J26: 0989866096 | K26: 台中市北區篤行路115號4樓
B27: 50183 | C27: WVWZZZCD3SW209684 | D27: 呂湘惠 | E27: W200391812 | F27: B | G27: 808 | H27: 0864 | I27: 0864979035808 | J27: 0934059742 | K27: 高雄市鼓山區美術東六街79號5樓
B28: 50184 | C28: TMBER9PJXS4085942 | D28: 廖偉廷 | E28: A127499066 | F28: B | G28: 013 | H28: 2697 | I28: 269506104024 | J28: 0983513977 | K28: 台北市文山區福興路82巷6弄3號
B29: 50185 | C29: TMBJN9NP8R7040539 | D29: 葉宗昊 | E29: A124233655 | F29: B | G29: 822 | H29: 0716 | I29: 716540237452 | J29: 0918760206 | K29: 基隆市暖暖街606號10號
B30: 50186 | C30: TMBLG9PS9ST101009 | D30: 全慶五金電料行 宋玉琴 | E30: 01961217 | F30: B | G30: 103 | H30: 0064 | I30: 0064106017481 | J30: 2585-1511 | K30: 台北市大同區環河北路2段223巷14號
B31: 50187 | C31: TMBER9PJ0S4102408 | D31: 羅欣怡 | E31: J222263208 | F31: B | G31: 808 | H31: 0439 | I31: 0439979016066 | J31: 0986586755 | K31: 新竹縣竹北市新國里17鄰新光三街12號2樓
B32: 50188 | C32: TMBJR9NU7S5082938 | D32: 孫淑賢 | E32: J220404283 | F32: B | G32: 822 | H32: 2190 | I32: 190540175350 | J32: 0937137445 | K32: 新竹市東區新光里20鄰高峰路126號
B33: 50189 | C33: TMBGK9NW6S3134491 | D33: 呂恩綺 | E33: H224545882 | F33: B | G33: 004 | H33: 0451 | I33: 045004880193 | J33: 0928287347 | K33: 新竹縣竹北市中興里16鄰嘉豐二街一段27號12樓
... B214: 50370 | C214: TMBEK9NW1S3131618 | D214: 詹智淵 | E214: F121500378 | F214: B | G214: 806 | H214: 1478 | I214: 21262000000372 | J214: 0928281960 | K214: 新北市板橋區中山路二段210號
B215: 50371 | C215: TMBJB9PS7ST101581 | D215: 林冠汝 | E215: F228305391 | F215: B | G215: 812 | I215: 06510900800500 | J215: 0916268171 | K215: 新北市板橋區光正街45巷20號4樓
B216: 50372 | C216: TMBLP0NZ9SC061140 | D216: 柳曉琪 | E216: K221609005 | F216: B | G216: 808 | H216: 0808 | I216: 0808979119443 | J216: 0932307763 | K216: 新北市板橋區莊敬路208巷8弄4號2樓
B217: 50373 | C217: TMBGK9NW1S3143793 | D217: 林禹棻 | E217: F226245436 | F217: P | G217: 700 | H217: 0021 | I217: 03110041831734 | J217: 0932882004 | K217: 新北市土城區廷和路125巷23號4樓
B218: 50374 | C218: TMBER9PJ8S4099550 | D218: 林明德 | E218: A120724931 | F218: C | G218: 216 | H218: 0016 | I218: 01000400417667 | J218: 0976427962 | K218: 花蓮縣吉安鄉光華10街102巷8號
B219: 50375 | C219: TMBJR0NX8SY151639 | D219: 邱顯嶸 | E219: A121165221 | F219: P | G219: 700 | H219: 0021 | I219: 00017250276095 | J219: 0926216329 | K219: 台北市中正區泉州街18巷9號
B220: 50376 | C220: TMBJB9PS9ST101601 | D220: 陳淑芬 | E220: R223028834 | F220: B | G220: 013 | H220: 2697 | I220: 269506017687 | J220: 0939322242 | K220: 台北市士林區天母西路48之7號5樓
B221: 50377 | C221: TMBLD9PSXST111265 | D221: 許足英 | E221: Y220315942 | F221: B | G221: 807 | H221: 1103 | I221: 11000400016144 | J221: 0910205982 | K221: 台北市北投區知行路227號4樓
B222: 50378 | C222: WVGZZZCT8SW560383 | D222: 王亭奕 | E222: F224201454 | F222: B | G222: 822 | H222: 0141 | I222: 141540059674 | J222: 0952-347-078 | K222: 台北市中正區廈門街81巷24號5樓
B223: 50379 | C223: WVGZZZA14SV111936 | D223: 許愛文 | E223: F220166507 | F223: B | G223: 006 | H223: 0039 | I223: 0030765032047 | J223: 0956-199-383 | K223: 新北市林口區文化二路一段20巷25弄27號5樓
B224: 50380 | C224: WVGZZZCTXSW560496 | D224: 林桂苹 | E224: E222240550 | F224: P | G224: 700 | H224: 0021 | I224: 01011600133401 | J224: 0975-361-134 | K224: 新北市林口區文化一路一段190巷7弄1號2樓之1
B225: 50381 | C225: WVWZZZCD3SW246461 | D225: 呂月華 | E225: H221166905 | F225: B | G225: 009 | H225: 5703 | I225: 57035126428400 | J225: 0925-796-200 | K225: 桃園市龜山區新興里17鄰自強南路235號
B226: 50382 | C226: WVWZZZCD0SW623649 | D226: 徐子文 | E226: H220020802 | F226: B | G226: 011 | H226: 0118 | I226: 11203000001703 | J226: 0910-142363 | K226: 桃園市桃園區永安里9鄰埔新路132號7樓
...

Sheet submitted
A1: 單號 | B1: 雅博單號 | C1: 車牌號 | D1: 收單日期 | E1: 審核狀態 | F1: 退稅方式 | G1: 海關號碼 | H1: 收件號碼 | I1: 退/補件說明 | J1: 審核完成日 | K1: 退稅通知書製表日期
A2: A000001 | B2: D-2025AB01-2000CC-1 | C2: CCL-1231 | D2: 2025/10/21 | E2: 審核完成 | F2: 直撥退車主 | G2: AB | H2: AB20251021092 | J2: 2025/11/14 | K2: 2025/12/05
A3: A000002 | B3: D-2025AB01-2000CC-2 | C3: CBY-6753 | D3: 2025/10/21 | E3: 審核完成 | F3: 直撥退車主 | G3: AB | H3: AB20251021092 | J3: 2025/11/14 | K3: 2025/12/05
A4: A000003 | B4: D-2025AB01-2000CC-3 | C4: BWR-3880 | D4: 2025/10/21 | E4: 審核完成 | F4: 直撥退車主 | G4: AB | H4: AB20251021092 | J4: 2025/11/14 | K4: 2025/12/05
A5: A000004 | B5: D-2025AB01-2000CC-4 | C5: CAH-1122 | D5: 2025/10/21 | E5: 審核完成 | F5: 直撥退車主 | G5: AB | H5: AB20251021092 | J5: 2025/11/14 | K5: 2025/12/05
A6: A000005 | B6: D-2025AB01-2000CC-5 | C6: CBM-5051 | D6: 2025/10/21 | E6: 審核完成 | F6: 直撥退車主 | G6: AB | H6: AB20251021092 | J6: 2025/11/14 | K6: 2025/12/05
A7: A000006 | B7: D-2025AB01-2000CC-6 | C7: BZS-2592 | D7: 2025/10/21 | E7: 審核完成 | F7: 直撥退車主 | G7: AB | H7: AB20251021092 | J7: 2025/11/14 | K7: 2025/12/05
A8: A000007 | B8: D-2025AB01-2000CC-7 | C8: CAB-9552 | D8: 2025/11/10 | E8: 審核完成 | F8: 直撥退車主 | G8: AB | H8: AB20251110152 | J8: 2025/11/21 | K8: 2025/12/12
A9: A000008 | B9: D-2025AB01-2000CC-8 | C9: CBM-3893 | D9: 2025/10/21 | E9: 審核完成 | F9: 直撥退車主 | G9: AB | H9: AB20251021092 | J9: 2025/11/14 | K9: 2025/12/05
A10: A000009 | B10: D-2025AB01-2000CC-9 | C10: CAR-7378 | D10: 2025/10/21 | E10: 審核完成 | F10: 直撥退車主 | G10: AB | H10: AB20251021092 | J10: 2025/11/14 | K10: 2025/12/05
A11: A000010 | B11: D-2025AB01-2000CC-10 | C11: BZT-5216 | D11: 2025/10/21 | E11: 審核完成 | F11: 直撥退車主 | G11: AB | H11: AB20251021092 | J11: 2025/11/14 | K11: 2025/12/05
A12: A000011 | B12: D-2025AB01-2000CC-11 | C12: CCN-2198 | D12: 2025/10/21 | E12: 審核完成 | F12: 直撥退車主 | G12: AB | H12: AB20251021092 | J12: 2025/11/14 | K12: 2025/12/05
A13: A000012 | B13: D-2025AB01-2000CC-12 | C13: CAR-2951 | D13: 2025/10/21 | E13: 審核完成 | F13: 直撥退車主 | G13: AB | H13: AB20251021092 | J13: 2025/11/14 | K13: 2025/12/05
... A418: A000239 | B418: D-2025AB09-2000CC-17 | C418: BWX-7683 | D418: 2025/11/20 | E418: 審核完成 | F418: 直撥退車主 | G418: AB | H418: AB20251120016 | J418: 2025/12/05 | K418: 2025/12/19
A419: A000240 | B419: D-2025AB09-2000CC-18 | C419: BQH-5066 | D419: 2025/12/02 | E419: 審核完成 | G419: AB | H419: AB20251202050
A420: A000241 | B420: D-2025AB09-2000CC-19 | C420: CAE-5338 | D420: 2025/11/20 | E420: 審核完成 | F420: 直撥退車主 | G420: AB | H420: AB20251120016 | J420: 2025/12/05 | K420: 2025/12/19
A421: A000242 | B421: D-2025AB09-2000CC-20 | C421: BQG-9505 | D421: 2025/11/20 | E421: 審核完成 | F421: 直撥退車主 | G421: AB | H421: AB20251120016 | J421: 2025/12/05 | K421: 2025/12/19
A422: A000243 | B422: D-2025AB09-2000CC-21 | C422: CAY-9918 | D422: 2025/11/20 | E422: 審核完成 | F422: 直撥退車主 | G422: AB | H422: AB20251120016 | J422: 2025/12/05 | K422: 2025/12/19
A423: A000244 | B423: D-2025AB09-2000CC-22 | C423: CAR-1032 | D423: 2025/11/20 | E423: 審核完成 | F423: 直撥退車主 | G423: AB | H423: AB20251120016 | J423: 2025/12/05 | K423: 2025/12/19
A424: A000245 | B424: D-2025AB09-2000CC-23 | C424: CAS-1030 | D424: 2025/11/20 | E424: 審核完成 | F424: 直撥退車主 | G424: AB | H424: AB20251120016 | J424: 2025/12/05 | K424: 2025/12/19
A425: A000246 | B425: D-2025AB09-2000CC-24 | C425: CAY-6501 | D425: 2025/11/20 | E425: 審核完成 | F425: 直撥退車主 | G425: AB | H425: AB20251120016 | J425: 2025/12/05 | K425: 2025/12/19
A426: A000247 | B426: D-2025AB09-2000CC-25 | C426: CAY-5635 | D426: 2025/11/20 | E426: 審核完成 | F426: 直撥退車主 | G426: AB | H426: AB20251120016 | J426: 2025/12/05 | K426: 2025/12/19
A427: A000248 | B427: D-2025AB09-2000CC-26 | C427: CAY-9225 | D427: 2025/11/20 | E427: 審核完成 | F427: 直撥退車主 | G427: AB | H427: AB20251120016 | J427: 2025/12/05 | K427: 2025/12/19
A428: A000249 | B428: D-2025AB09-2000CC-27 | C428: CAY-8110 | D428: 2025/11/20 | E428: 審核完成 | F428: 直撥退車主 | G428: AB | H428: AB20251120016 | J428: 2025/12/05 | K428: 2025/12/19
A429: A000250 | B429: D-2025AB09-2000CC-28 | C429: CAR-6632 | D429: 2025/11/20 | E429: 審核完成 | F429: 直撥退車主 | G429: AB | H429: AB20251120016 | J429: 2025/12/05 | K429: 2025/12/19
A430: A000251 | B430: D-2025AB09-2000CC-29 | C430: CAY-8035 | D430: 2025/11/20 | E430: 審核完成 | F430: 直撥退車主 | G430: AB | H430: AB20251120016 | J430: 2025/12/05 | K430: 2025/12/19
A431: A000252 | B431: D-2025AB09-2000CC-30 | C431: CAY-3926 | D431: 2025/11/20 | E431: 審核完成 | F431: 直撥退車主 | G431: AB | H431: AB20251120016 | J431: 2025/12/05 | K431: 2025/12/19
... A666: A001521 | B666: D-2025AB12_2000CC-55 | C666: CAR-7086 | D666: 2025/12/02 | E666: 審核完成 | F666: 直撥退車主 | G666: AB | H666: AB20251202054 | J666: 2025/12/11 | K666: 2025/12/26
A667: A001522 | B667: D-2025AB12_2000CC-56 | C667: CBB-3525 | D667: 2025/12/02 | E667: 審核完成 | G667: AB | H667: AB20251202054 | J667: 2025/12/11
A668: A001523 | B668: D-2025AB12_2000CC-57 | C668: CBK-3177 | D668: 2025/12/02 | E668: 審核完成 | F668: 直撥退車主 | G668: AB | H668: AB20251202054 | J668: 2025/12/11 | K668: 2025/12/26
A669: A001524 | B669: D-2025AB12_2000CC-58 | C669: CBF-2025 | D669: 2025/12/02 | E669: 審核完成 | F669: 直撥退車主 | G669: AB | H669: AB20251202054 | J669: 2025/12/11 | K669: 2025/12/26
A670: A001525 | B670: D-2025AB12_2000CC-59 | C670: CAR-5106 | D670: 2025/12/02 | E670: 審核完成 | F670: 直撥退車主 | G670: AB | H670: AB20251202054 | J670: 2025/12/11 | K670: 2025/12/26
A671: A001526 | B671: D-2025AB12_2000CC-60 | C671: BWX-9219 | D671: 2025/12/02 | E671: 審核完成 | F671: 直撥退車主 | G671: AB | H671: AB20251202054 | J671: 2025/12/11 | K671: 2025/12/26
A672: A001527 | B672: D-2025AB12_2000CC-61 | C672: CAD-5993 | D672: 2025/12/02 | E672: 審核完成 | F672: 直撥退車主 | G672: AB | H672: AB20251202054 | J672: 2025/12/11 | K672: 2025/12/26
A673: A001528 | B673: D-2025AB12_2000CC-62 | C673: CAS-1285 | D673: 2025/12/02 | E673: 審核完成 | F673: 直撥退車主 | G673: AB | H673: AB20251202054 | J673: 2025/12/11 | K673: 2025/12/26
A674: A001529 | B674: D-2025AB12_2000CC-63 | C674: CCB-0206 | D674: 2025/12/02 | E674: 審核完成 | F674: 直撥退車主 | G674: AB | H674: AB20251202054 | J674: 2025/12/11 | K674: 2025/12/26
A675: A001530 | B675: D-2025AB12_2000CC-64 | C675: BWX-9259 | D675: 2025/12/02 | E675: 審核完成 | F675: 直撥退車主 | G675: AB | H675: AB20251202054 | J675: 2025/12/11 | K675: 2025/12/26
A676: A001531 | B676: D-2025AB12_2000CC-65 | C676: CCN-7677 | D676: 2025/12/02 | E676: 審核完成 | F676: 直撥退車主 | G676: AB | H676: AB20251202054 | J676: 2025/12/11 | K676: 2025/12/26
A677: A001532 | B677: D-2025AB12_2000CC-66 | C677: CAH-1380 | D677: 2025/12/02 | E677: 審核完成 | F677: 直撥退車主 | G677: AB | H677: AB20251202054 | J677: 2025/12/11 | K677: 2025/12/26
A678: A001533 | B678: D-2025AB12_2000CC-67 | C678: CAH-5505 | D678: 2025/12/02 | E678: 審核完成 | F678: 直撥退車主 | G678: AB | H678: AB20251202054 | J678: 2025/12/11 | K678: 2025/12/26
...

Sheet Sheet1
A1: 牌照號碼 | B1: 車身號碼 | C1: 送件案號
A2: CCL-1231 | B2: TMBAR0NX1SM057335 | C2: 2025AB01-1
A3: CBY-6753 | B3: TMBER9PJ6S4099241 | C3: 2025AB01-2
A4: BWR-3880 | B4: WVWZZZCD0SW246322 | C4: 2025AB01-3
A5: CAH-1122 | B5: WAUZZZGY7SA148167 | C5: 2025AB01-4
A6: CBM-5051 | B6: TMBLD9PS9ST075259 | C6: 2025AB01-5
A7: BZS-2592 | B7: WVGZZZC12RY088372 | C7: 2025AB01-6
A8: CAB-9552 | B8: TMBER9PJ5S4091941 | C8: 2025AB01-7
A9: CBM-3893 | B9: WVGZZZC13RY089062 | C9: 2025AB01-8
A10: CAR-7378 | B10: WVWZZZCD4SW198579 | C10: 2025AB01-9
A11: BZT-5216 | B11: TMBJV0NX5SY151562 | C11: 2025AB01-10
A12: CCN-2198 | B12: TMBLG9PS7ST093086 | C12: 2025AB01-11
... A470: CCL-0975 | B470: TMBJB9PS8ST078781 | C470: 2025AB09-69

Sheet Sheet2
A1: 單號 | B1: 雅博單號 | C1: 車牌號 | D1: 收單日期 | E1: 審核狀態 | F1: 退稅方式 | G1: 海關號碼 | H1: 收件號碼 | I1: 退/補件說明 | J1: 審核完成日 | K1: 退稅通知書製表日期
A2: A000856 | B2: D-2025AB16-2000CC-24 | C2: CBK-6812 | D2: 2026/01/01 | E2: 審核完成 | G2: AB | H2: AB20260101263 | J2: 2026/02/02
A3: A001969 | B3: D-2026AB01-2000CC-1 | C3: RFX-8638 | D3: 2026/01/05 | E3: 審核完成 | G3: AB | H3: AB20260105269 | J3: 2026/02/02
A4: A001970 | B4: D-2026AB01-2000CC-2 | C4: RFX-8626 | D4: 2026/01/05 | E4: 審核完成 | G4: AB | H4: AB20260105269 | J4: 2026/02/02
A5: A001971 | B5: D-2026AB01-2000CC-3 | C5: CBK-3787 | D5: 2026/01/05 | E5: 審核完成 | G5: AB | H5: AB20260105269 | J5: 2026/02/02
A6: A001972 | B6: D-2026AB01-2000CC-4 | C6: CBK-2360 | D6: 2026/01/05 | E6: 審核完成 | G6: AB | H6: AB20260105269 | J6: 2026/02/02
A7: A001973 | B7: D-2026AB01-2000CC-5 | C7: CAY-6716 | D7: 2026/01/05 | E7: 審核完成 | G7: AB | H7: AB20260105269 | J7: 2026/02/02
A8: A001974 | B8: D-2026AB01-2000CC-6 | C8: CAY-8731 | D8: 2026/01/05 | E8: 審核完成 | G8: AB | H8: AB20260105269 | J8: 2026/02/02
A9: A001976 | B9: D-2026AB01-2000CC-7 | C9: CAE-9727 | D9: 2026/01/05 | E9: 審核完成 | G9: AB | H9: AB20260105269 | J9: 2026/02/02
A10: A001977 | B10: D-2026AB01-2000CC-8 | C10: CBN-7557 | D10: 2026/01/05 | E10: 審核完成 | G10: AB | H10: AB20260105269 | J10: 2026/02/02
A11: A001978 | B11: D-2026AB01-2000CC-9 | C11: CBU-8686 | D11: 2026/01/05 | E11: 審核完成 | G11: AB | H11: AB20260105269 | J11: 2026/02/02
A12: A001979 | B12: D-2026AB01-2000CC-10 | C12: CBQ-3517 | D12: 2026/01/05 | E12: 審核完成 | G12: AB | H12: AB20260105269 | J12: 2026/02/02
A13: A001980 | B13: D-2026AB01-2000CC-11 | C13: CBS-1061 | D13: 2026/01/05 | E13: 審核完成 | G13: AB | H13: AB20260105269 | J13: 2026/02/02
... A66: A002121 | B66: D-2026AB01-2000CC-64 | C66: CAH-5325 | D66: 2026/01/05 | E66: 審核完成 | G66: AB | H66: AB20260105269 | J66: 2026/02/02
A67: A002122 | B67: D-2026AB01-2000CC-65 | C67: CAH-9939 | D67: 2026/01/14 | E67: 審核中 | G67: AB | H67: AB20260114319
A68: A002124 | B68: D-2026AB01-2000CC-66 | C68: CAH-5315 | D68: 2026/01/14 | E68: 審核中 | G68: AB | H68: AB20260114319
A69: A002125 | B69: D-2026AB01-2000CC-67 | C69: BPN-3168 | D69: 2026/01/05 | E69: 審核完成 | G69: AB | H69: AB20260105269 | J69: 2026/02/02
A70: A002126 | B70: D-2026AB01-2000CC-68 | C70: CCN-8766 | D70: 2026/01/05 | E70: 審核完成 | G70: AB | H70: AB20260105269 | J70: 2026/02/02
A71: A002127 | B71: D-2026AB01-2000CC-69 | C71: CCN-3637 | D71: 2026/01/05 | E71: 審核完成 | G71: AB | H71: AB20260105269 | J71: 2026/02/02
A72: A002128 | B72: D-2026AB01-2000CC-70 | C72: CCN-3630 | D72: 2026/01/05 | E72: 審核完成 | G72: AB | H72: AB20260105269 | J72: 2026/02/02
A73: A002129 | B73: D-2026AB01-2000CC-71 | C73: CCN-3627 | D73: 2026/01/05 | E73: 審核完成 | G73: AB | H73: AB20260105269 | J73: 2026/02/02
A74: A002130 | B74: D-2026AB01-2000CC-72 | C74: CCM-9672 | D74: 2026/01/05 | E74: 審核完成 | G74: AB | H74: AB20260105269 | J74: 2026/02/02
A75: A002131 | B75: D-2026AB01-2000CC-73 | C75: CCN-3632 | D75: 2026/01/05 | E75: 審核完成 | G75: AB | H75: AB20260105269 | J75: 2026/02/02
A76: A002132 | B76: D-2026AB01-2000CC-74 | C76: CCN-3631 | D76: 2026/01/05 | E76: 審核完成 | G76: AB | H76: AB20260105269 | J76: 2026/02/02
A77: A002134 | B77: D-2026AB01-2000CC-75 | C77: CCN-3625 | D77: 2026/01/05 | E77: 審核完成 | G77: AB | H77: AB20260105269 | J77: 2026/02/02
A78: A002135 | B78: D-2026AB01-2000CC-76 | C78: CCN-2733 | D78: 2026/01/05 | E78: 審核完成 | G78: AB | H78: AB20260105269 | J78: 2026/02/02
A79: A002136 | B79: D-2026AB01-2000CC-77 | C79: CCN-1706 | D79: 2026/01/05 | E79: 審核完成 | G79: AB | H79: AB20260105269 | J79: 2026/02/02
A80: A002137 | B80: D-2026AB01-2000CC-78 | C80: CCN-3621 | D80: 2026/01/05 | E80: 審核完成 | G80: AB | H80: AB20260105269 | J80: 2026/02/02
... A90: A002146 | B90: D-2026AB02-2000CC-8 | C90: BZF-7879 | D90: 2026/01/05 | E90: 審核完成 | G90: AB | H90: AB20260105270 | J90: 2026/02/02
A91: A002147 | B91: D-2026AB02-2000CC-9 | C91: CBQ-2526 | D91: 2026/01/14 | E91: 審核中 | G91: AB | H91: AB20260114319
A92: A002148 | B92: D-2026AB02-2000CC-10 | C92: CBQ-1827 | D92: 2026/01/14 | E92: 審核中 | G92: AB | H92: AB20260114319
A93: A002149 | B93: D-2026AB02-2000CC-11 | C93: CBS-1383 | D93: 2026/01/14 | E93: 審核中 | G93: AB | H93: AB20260114319
A94: A002150 | B94: D-2026AB02-2000CC-12 | C94: CBS-0175 | D94: 2026/01/05 | E94: 審核完成 | G94: AB | H94: AB20260105270 | J94: 2026/02/02
A95: A002151 | B95: D-2026AB02-2000CC-13 | C95: CBP-7078 | D95: 2026/01/14 | E95: 審核中 | G95: AB | H95: AB20260114319
A96: A002152 | B96: D-2026AB02-2000CC-14 | C96: CBP-2929 | D96: 2026/01/05 | E96: 審核完成 | G96: AB | H96: AB20260105270 | J96: 2026/02/02
A97: A002153 | B97: D-2026AB02-2000CC-15 | C97: CBF-2663 | D97: 2026/01/05 | E97: 審核完成 | G97: AB | H97: AB20260105270 | J97: 2026/02/02
A98: A002155 | B98: D-2026AB02-2000CC-16 | C98: CBK-8961 | D98: 2026/01/05 | E98: 審核完成 | G98: AB | H98: AB20260105270 | J98: 2026/02/02
A99: A002156 | B99: D-2026AB02-2000CC-17 | C99: BXW-5669 | D99: 2026/01/05 | E99: 審核完成 | G99: AB | H99: AB20260105270 | J99: 2026/02/02
A100: A002157 | B100: D-2026AB02-2000CC-18 | C100: BNW-7239 | D100: 2026/01/14 | E100: 審核中 | G100: AB | H100: AB20260114319
A101: A002158 | B101: D-2026AB02-2000CC-19 | C101: BZF-7939 | D101: 2026/01/14 | E101: 審核中 | G101: AB | H101: AB20260114319
...
